[2024-05-29T17:03:34.431+0000] {task_context_logger.py:104} ERROR - Executor reports task instance <TaskInstance: test_1.task_1 scheduled__2024-03-18T00:00:00+00:00 [queued]> finished (failed) although the task says it's queued. (Info: None) Was the task killed externally?
